Workbook

Sheet Programação_Semana
A1: Projeto | B1: Descrição do Projeto | C1: Data Programacao | D1: Status Programacao | E1: Tipo Intervencao | F1: Numero PowerON | G1: Equipamentos | H1: Horario Inicio | I1: Horario Fim | J1: Contratada | K1: Localização X (Longitude) | L1: Localização Y (Latitude)
A2: DAC/A.LES.25.00703 | B2: Remoção de Poste | C2: 46167 | D2: Liberado para Execução | E2: FI | F2: 16178484 | G2: 010ET229477 | H2: 46167.583 | I2: 46167.667 | J2: Start Engenharia (Área 8B, 9 e 11) NEC | K2: =_xlfn.XLOOKUP(G:G,Planilha1!A:A,Planilha1!C:C,"NÃO ENCONTRADO") -> -46.4823465930684 | L2: =_xlfn.XLOOKUP(G:G,Planilha1!A:A,Planilha1!D:D,"Não encontrado") -> -23.6797157591265
A3: DMP/A.LES.22.05524 | B3: Reforma de Rede Secundária | C3: 46167 | D3: Liberado para Execução | E3: FI | F3: 16170780 | G3: 352ET073772 | H3: 46167.396 | I3: 46167.521 | J3: Engelmig (Área 11) NEC e UPS | K3: =_xlfn.XLOOKUP(G:G,Planilha1!A:A,Planilha1!C:C,"NÃO ENCONTRADO") -> -46.391169126889 | L3: =_xlfn.XLOOKUP(G:G,Planilha1!A:A,Planilha1!D:D,"Não encontrado") -> -23.5117493826622
A4: DMP/A.LES.21.28198 | B4: Reforma de Rede Secundária | C4: 46167 | D4: Liberado para Execução | E4: OLVR | G4: 352ET032397 | H4: 46167.333 | I4: 46167.688 | J4: Engelmig (Área 11) NEC e UPS | K4: =_xlfn.XLOOKUP(G:G,Planilha1!A:A,Planilha1!C:C,"NÃO ENCONTRADO") -> -46.3900806724785 | L4: =_xlfn.XLOOKUP(G:G,Planilha1!A:A,Planilha1!D:D,"Não encontrado") -> -23.5075472990191
A5: DMP/A.LES.20.06242 | B5: Reforma de Rede Secundária | C5: 46167 | D5: Liberado para Execução | E5: OLVR | G5: 352ET055378 | H5: 46167.333 | I5: 46167.688 | J5: Engelmig (Área 11) NEC e UPS | K5: =_xlfn.XLOOKUP(G:G,Planilha1!A:A,Planilha1!C:C,"NÃO ENCONTRADO") -> -46.3750869907994 | L5: =_xlfn.XLOOKUP(G:G,Planilha1!A:A,Planilha1!D:D,"Não encontrado") -> -23.4927281855108
A6: DMP/A.LES.25.04887 | B6: Reforma de Rede Secundaria RTRI | C6: 46167 | D6: Liberado para Execução | E6: FI | F6: 16171013 | G6: 356ET005108 | H6: 46167.417 | I6: 46167.583 | J6: Engelmig (Área 11) NEC e UPS | K6: =_xlfn.XLOOKUP(G:G,Planilha1!A:A,Planilha1!C:C,"NÃO ENCONTRADO") -> -46.4556245887762 | L6: =_xlfn.XLOOKUP(G:G,Planilha1!A:A,Planilha1!D:D,"Não encontrado") -> -23.5257360598735
A7: DMP/A.LES.24.05583 | B7: Reforma de Rede Secundaria RTRI | C7: 46167 | D7: Liberado para Execução | E7: FI | F7: 16170595 | G7: 015ET003629 | H7: 46167.354 | I7: 46167.458 | J7: Engelmig (Área 11) NEC e UPS | K7: =_xlfn.XLOOKUP(G:G,Planilha1!A:A,Planilha1!C:C,"NÃO ENCONTRADO") -> -46.4230873069374 | L7: =_xlfn.XLOOKUP(G:G,Planilha1!A:A,Planilha1!D:D,"Não encontrado") -> -23.668893776122
A8: DMP/A.LES.24.01909 | B8: Reforma de Rede Secundaria RTRI | C8: 46167 | D8: Liberado para Execução | E8: FI | F8: 16170519 | G8: 010ET034195 | H8: 46167.521 | I8: 46167.646 | J8: Engelmig (Área 11) NEC e UPS | K8: =_xlfn.XLOOKUP(G:G,Planilha1!A:A,Planilha1!C:C,"NÃO ENCONTRADO") -> -46.5257192445865 | L8: =_xlfn.XLOOKUP(G:G,Planilha1!A:A,Planilha1!D:D,"Não encontrado") -> -23.6409274545918
A9: DMP/A.LES.21.28265 | B9: Reforma de Rede Secundária | C9: 46167 | D9: Liberado para Execução | E9: FI | F9: 16170845 | G9: 352ET058518 | H9: 46167.417 | I9: 46167.5 | J9: Engelmig (Área 11) NEC e UPS | K9: =_xlfn.XLOOKUP(G:G,Planilha1!A:A,Planilha1!C:C,"NÃO ENCONTRADO") -> -46.4161027235292 | L9: =_xlfn.XLOOKUP(G:G,Planilha1!A:A,Planilha1!D:D,"Não encontrado") -> -23.4796903172671
A10: DMP/A.LES.21.28225 | B10: Reforma de Rede Secundária | C10: 46167 | D10: Liberado para Execução | E10: OLVR | G10: 356ET161667 | H10: 46167.354 | I10: 46167.688 | J10: Engelmig (Área 11) NEC e UPS | K10: =_xlfn.XLOOKUP(G:G,Planilha1!A:A,Planilha1!C:C,"NÃO ENCONTRADO") -> -46.4725247854146 | L10: =_xlfn.XLOOKUP(G:G,Planilha1!A:A,Planilha1!D:D,"Não encontrado") -> -23.5640482738828
A11: DMP/A.LES.22.01002 | B11: Reforma de Rede Secundária | C11: 46167 | D11: Liberado para Execução | E11: OLVR | G11: 356ET029453 | H11: 46167.354 | I11: 46167.688 | J11: Engelmig (Área 11) NEC e UPS | K11: =_xlfn.XLOOKUP(G:G,Planilha1!A:A,Planilha1!C:C,"NÃO ENCONTRADO") -> -46.4230355151535 | L11: =_xlfn.XLOOKUP(G:G,Planilha1!A:A,Planilha1!D:D,"Não encontrado") -> -23.6153712025164
A12: DMP/A.LES.22.07454 | B12: Reforma de Rede Secundária | C12: 46167 | D12: Liberado para Execução | E12: OLVR | G12: ET-160966 | H12: 46167.354 | I12: 46167.688 | J12: Engelmig (Área 11) NEC e UPS | K12: =_xlfn.XLOOKUP(G:G,Planilha1!A:A,Planilha1!C:C,"NÃO ENCONTRADO") -> NÃO ENCONTRADO | L12: =_xlfn.XLOOKUP(G:G,Planilha1!A:A,Planilha1!D:D,"Não encontrado") -> Não encontrado
A13: DAC/A.LES.25.00838 | B13: Alteração de Carga | C13: 46167 | D13: Liberado para Execução | E13: FI | F13: 16178993 | G13: 015ET221067 | H13: 46167.583 | I13: 46167.708 | J13: Start Engenharia (Área 8B, 9 e 11) NEC | K13: =_xlfn.XLOOKUP(G:G,Planilha1!A:A,Planilha1!C:C,"NÃO ENCONTRADO") -> -46.4489672817882 | L13: =_xlfn.XLOOKUP(G:G,Planilha1!A:A,Planilha1!D:D,"Não encontrado") -> -23.6757998794377
A14: DAC/A.ABC.26.00021 | B14: Ligação Nova | C14: 46167 | D14: Liberado para Execução | E14: FI | F14: 16170590 | G14: 020ET088807 | H14: 46167.417 | I14: 46167.542 | J14: Start Engenharia (Área 8B, 9 e 11) NEC | K14: =_xlfn.XLOOKUP(G:G,Planilha1!A:A,Planilha1!C:C,"NÃO ENCONTRADO") -> -46.4161784263815 | L14: =_xlfn.XLOOKUP(G:G,Planilha1!A:A,Planilha1!D:D,"Não encontrado") -> -23.7693276933029
A15: DAC/A.LES.25.00715 | B15: Ligação Provisória | C15: 46167 | D15: Liberado para Execução | E15: FI | F15: 16179061 | G15: 356ET006973 | H15: 46167.375 | I15: 46167.542 | J15: Start Engenharia (Área 8B, 9 e 11) NEC | K15: =_xlfn.XLOOKUP(G:G,Planilha1!A:A,Planilha1!C:C,"NÃO ENCONTRADO") -> -46.4436093478508 | L15: =_xlfn.XLOOKUP(G:G,Planilha1!A:A,Planilha1!D:D,"Não encontrado") -> -23.5411914142455
A16: DAC/A.LES.25.00958 | B16: Ligação Nova | C16: 46167 | D16: Liberado para Execução | E16: FI | F16: 16179570 | G16: 356ET167647 | H16: 46167.417 | I16: 46167.583 | J16: Start Engenharia (Área 8B, 9 e 11) NEC | K16: =_xlfn.XLOOKUP(G:G,Planilha1!A:A,Planilha1!C:C,"NÃO ENCONTRADO") -> -46.4056122617708 | L16: =_xlfn.XLOOKUP(G:G,Planilha1!A:A,Planilha1!D:D,"Não encontrado") -> -23.5335561977065
A17: DAC/A.LES.26.00406 | B17: Ligação Nova | C17: 46167 | D17: Liberado para Execução | E17: FI | F17: 16178764 | G17: 020BF025865 | H17: 46167.417 | I17: 46167.583 | J17: Start Engenharia (Área 8B, 9 e 11) NEC | K17: =_xlfn.XLOOKUP(G:G,Planilha1!A:A,Planilha1!C:C,"NÃO ENCONTRADO") -> -46.3818843904952 | L17: =_xlfn.XLOOKUP(G:G,Planilha1!A:A,Planilha1!D:D,"Não encontrado") -> -23.689443554704
A18: DAC/A.LES.25.00981 | B18: Ligação Nova | C18: 46167 | D18: Liberado para Execução | E18: OLVR | G18: 010ET220725 | H18: 46167.417 | I18: 46167.583 | J18: Start Engenharia (Área 8B, 9 e 11) NEC | K18: =_xlfn.XLOOKUP(G:G,Planilha1!A:A,Planilha1!C:C,"NÃO ENCONTRADO") -> -46.5096866792029 | L18: =_xlfn.XLOOKUP(G:G,Planilha1!A:A,Planilha1!D:D,"Não encontrado") -> -23.7134068983585
A19: DAC/A.LES.25.01249 | B19: Ligação Nova | C19: 46167 | D19: Liberado para Execução | E19: FI | F19: 16187207 | G19: 352BF058580 | H19: 46167.417 | I19: 46167.583 | J19: Conecta Obras Extras (Área 8B, 9 e 11) NEC | K19: =_xlfn.XLOOKUP(G:G,Planilha1!A:A,Planilha1!C:C,"NÃO ENCONTRADO") -> -46.5132523033948 | L19: =_xlfn.XLOOKUP(G:G,Planilha1!A:A,Planilha1!D:D,"Não encontrado") -> -23.515192787827
A20: DAC/A.LES.25.01283 | B20: Ligação Nova | C20: 46167 | D20: Liberado para Execução | E20: FI | F20: 16187207 | G20: 352BF058580 | H20: 46167.417 | I20: 46167.583 | J20: Conecta Obras Extras (Área 8B, 9 e 11) NEC | K20: =_xlfn.XLOOKUP(G:G,Planilha1!A:A,Planilha1!C:C,"NÃO ENCONTRADO") -> -46.5132523033948 | L20: =_xlfn.XLOOKUP(G:G,Planilha1!A:A,Planilha1!D:D,"Não encontrado") -> -23.515192787827
A21: DMP/A.LES.26.02101 | B21: Substituição de Poste em Mau Estado | C21: 46168 | D21: Liberado para Execução | E21: FI | F21: 16188286 | G21: 355ET060608 | H21: 46168.417 | I21: 46168.583 | J21: Start Engenharia (Área 8B, 9 e 11) NEC | K21: =_xlfn.XLOOKUP(G:G,Planilha1!A:A,Planilha1!C:C,"NÃO ENCONTRADO") -> NÃO ENCONTRADO | L21: =_xlfn.XLOOKUP(G:G,Planilha1!A:A,Planilha1!D:D,"Não encontrado") -> Não encontrado
A22: DMP/A.LES.24.04962 | B22: Rede Compacta | C22: 46168 | D22: Liberado para Execução | E22: PIE | F22: 16251645 | G22: ET-066015 | H22: 46168.417 | I22: 46168.583 | J22: ZZOUT-Start Área 8B+11 (Contrato Antigo) | K22: =_xlfn.XLOOKUP(G:G,Planilha1!A:A,Planilha1!C:C,"NÃO ENCONTRADO") -> NÃO ENCONTRADO | L22: =_xlfn.XLOOKUP(G:G,Planilha1!A:A,Planilha1!D:D,"Não encontrado") -> Não encontrado
A23: DMP/A.LES.24.04961 | B23: Rede Compacta | C23: 46168 | D23: Liberado para Execução | E23: PIE | F23: 16251645 | G23: 353ET013232 | H23: 46168.417 | I23: 46168.583 | J23: Start Engenharia (Área 8B, 9 e 11) NEC | K23: =_xlfn.XLOOKUP(G:G,Planilha1!A:A,Planilha1!C:C,"NÃO ENCONTRADO") -> -46.5318243574902 | L23: =_xlfn.XLOOKUP(G:G,Planilha1!A:A,Planilha1!D:D,"Não encontrado") -> -23.5581110442241
A24: DMP/A.LES.24.04905 | B24: Rede Compacta | C24: 46168 | D24: Liberado para Execução | E24: PIE | F24: 16251645 | G24: 353ET006123 | H24: 46168.417 | I24: 46168.583 | J24: ZZOUT-Start Área 8B+11 (Contrato Antigo) | K24: =_xlfn.XLOOKUP(G:G,Planilha1!A:A,Planilha1!C:C,"NÃO ENCONTRADO") -> -46.5306276021219 | L24: =_xlfn.XLOOKUP(G:G,Planilha1!A:A,Planilha1!D:D,"Não encontrado") -> -23.5585209900397
A25: DMP/A.LES.25.02498 | B25: Reforma de Rede Secundaria RTRI | C25: 46168 | D25: Liberado para Execução | E25: FI | F25: 16184866 | G25: 010ET081182 | H25: 46168.417 | I25: 46168.583 | J25: Engelmig (Área 11) NEC e UPS | K25: =_xlfn.XLOOKUP(G:G,Planilha1!A:A,Planilha1!C:C,"NÃO ENCONTRADO") -> -46.5106669955678 | L25: =_xlfn.XLOOKUP(G:G,Planilha1!A:A,Planilha1!D:D,"Não encontrado") -> -23.6941926239155
A26: DMP/A.LES.22.07332 | B26: Reforma de Rede Secundária | C26: 46168 | D26: Liberado para Execução | E26: OLVR | G26: 356ET162686 | H26: 46168.333 | I26: 46168.667 | J26: Engelmig (Área 11) NEC e UPS | K26: =_xlfn.XLOOKUP(G:G,Planilha1!A:A,Planilha1!C:C,"NÃO ENCONTRADO") -> -46.4577169031599 | L26: =_xlfn.XLOOKUP(G:G,Planilha1!A:A,Planilha1!D:D,"Não encontrado") -> -23.522278707595
A27: DAC/A.LES.25.01255 | B27: Ligação Nova | C27: 46168 | D27: Liberado para Execução | E27: FI | F27: 16188047 | G27: 352ET163092 | H27: 46168.417 | I27: 46168.583 | J27: Conecta Obras Extras (Área 8B, 9 e 11) NEC | K27: =_xlfn.XLOOKUP(G:G,Planilha1!A:A,Planilha1!C:C,"NÃO ENCONTRADO") -> -46.5026428419241 | L27: =_xlfn.XLOOKUP(G:G,Planilha1!A:A,Planilha1!D:D,"Não encontrado") -> -23.4883001454713
A28: DAC/A.LES.25.01179 | B28: Ligação Nova | C28: 46168 | D28: Liberado para Execução | E28: FI | F28: 16188047 | G28: 352ET163092 | H28: 46168.417 | I28: 46168.583 | J28: Conecta Obras Extras (Área 8B, 9 e 11) NEC | K28: =_xlfn.XLOOKUP(G:G,Planilha1!A:A,Planilha1!C:C,"NÃO ENCONTRADO") -> -46.5026428419241 | L28: =_xlfn.XLOOKUP(G:G,Planilha1!A:A,Planilha1!D:D,"Não encontrado") -> -23.4883001454713
A29: DAC/A.LES.25.01112 | B29: Remoção de Poste | C29: 46168 | D29: Liberado para Execução | E29: FI | F29: 16188104 | G29: 353ET037967 | H29: 46168.417 | I29: 46168.583 | J29: Conecta Obras Extras (Área 8B, 9 e 11) NEC | K29: =_xlfn.XLOOKUP(G:G,Planilha1!A:A,Planilha1!C:C,"NÃO ENCONTRADO") -> -46.5119907620277 | L29: =_xlfn.XLOOKUP(G:G,Planilha1!A:A,Planilha1!D:D,"Não encontrado") -> -23.5661528272021
A30: DAC/A.LES.26.00201 | B30: Alteração de Carga | C30: 46168 | D30: Liberado para Execução | E30: OLVR | G30: 356ET063360 | H30: 46168.083 | I30: 46168.229 | J30: Start Engenharia (Área 8B, 9 e 11) NEC | K30: =_xlfn.XLOOKUP(G:G,Planilha1!A:A,Planilha1!C:C,"NÃO ENCONTRADO") -> -46.4486205864702 | L30: =_xlfn.XLOOKUP(G:G,Planilha1!A:A,Planilha1!D:D,"Não encontrado") -> -23.5697423058042
A31: DAC/A.LES.25.00723 | B31: Ligação Nova | C31: 46169 | D31: Liberado para Execução | E31: FI | F31: 16235175 | G31: 356ET052591 | H31: 46169.417 | I31: 46169.542 | J31: Start Engenharia (Área 8B, 9 e 11) NEC | K31: =_xlfn.XLOOKUP(G:G,Planilha1!A:A,Planilha1!C:C,"NÃO ENCONTRADO") -> -46.4194938206928 | L31: =_xlfn.XLOOKUP(G:G,Planilha1!A:A,Planilha1!D:D,"Não encontrado") -> -23.5848048277106
A32: DMP/A.LES.25.04129 | B32: Reforma de Rede Secundaria RTRI | C32: 46169 | D32: Liberado para Execução | E32: FI | F32: 16200998 | G32: 356ET055935 | H32: 46169.396 | I32: 46169.521 | J32: Start Engenharia (Área 8B, 9 e 11) NEC | K32: =_xlfn.XLOOKUP(G:G,Planilha1!A:A,Planilha1!C:C,"NÃO ENCONTRADO") -> -46.4755472362478 | L32: =_xlfn.XLOOKUP(G:G,Planilha1!A:A,Planilha1!D:D,"Não encontrado") -> -23.5728631468264
A33: DMP/A.LES.25.05795 | B33: Reforma de Rede Secundaria RTRI | C33: 46169 | D33: Liberado para Execução | E33: FI | F33: 16201080 | G33: 356ET027458 | H33: 46169.417 | I33: 46169.542 | J33: Start Engenharia (Área 8B, 9 e 11) NEC | K33: =_xlfn.XLOOKUP(G:G,Planilha1!A:A,Planilha1!C:C,"NÃO ENCONTRADO") -> -46.4543680412366 | L33: =_xlfn.XLOOKUP(G:G,Planilha1!A:A,Planilha1!D:D,"Não encontrado") -> -23.6155079738962
A34: DAC/A.LES.25.01193 | B34: Ligação Nova | C34: 46169 | D34: Liberado para Execução | E34: PIE | F34: 16211084 | G34: 353ET010105 | H34: 46169.021 | I34: 46169.188 | J34: Start Engenharia (Área 8B, 9 e 11) NEC | K34: =_xlfn.XLOOKUP(G:G,Planilha1!A:A,Planilha1!C:C,"NÃO ENCONTRADO") -> -46.6049054054894 | L34: =_xlfn.XLOOKUP(G:G,Planilha1!A:A,Planilha1!D:D,"Não encontrado") -> -23.5308054058955
A35: DMP/A.LES.25.02499 | B35: Reforma de Rede Secundaria RTRI | C35: 46169 | D35: Liberado para Execução | E35: FI | F35: 16201701 | G35: 356ET160603 | H35: 46169.438 | I35: 46169.604 | J35: Engelmig (Área 11) NEC e UPS | K35: =_xlfn.XLOOKUP(G:G,Planilha1!A:A,Planilha1!C:C,"NÃO ENCONTRADO") -> -46.4073549484051 | L35: =_xlfn.XLOOKUP(G:G,Planilha1!A:A,Planilha1!D:D,"Não encontrado") -> -23.5271020875168
A36: DAC/A.LES.26.00347 | B36: Alteração de Carga | C36: 46169 | D36: Liberado para Execução | E36: FI | F36: 16212244 | G36: 353ET042932 | H36: 46169.417 | I36: 46169.583 | J36: Start Engenharia (Área 8B, 9 e 11) NEC | K36: =_xlfn.XLOOKUP(G:G,Planilha1!A:A,Planilha1!C:C,"NÃO ENCONTRADO") -> -46.6100057710408 | L36: =_xlfn.XLOOKUP(G:G,Planilha1!A:A,Planilha1!D:D,"Não encontrado") -> -23.5488792205493
A37: DAC/A.LES.26.00199 | B37: Ligação Nova | C37: 46169 | D37: Liberado para Execução | E37: FI | F37: 16200965 | G37: 353ET065828 | H37: 46169.417 | I37: 46169.583 | J37: Start Engenharia (Área 8B, 9 e 11) NEC | K37: =_xlfn.XLOOKUP(G:G,Planilha1!A:A,Planilha1!C:C,"NÃO ENCONTRADO") -> -46.5081271050568 | L37: =_xlfn.XLOOKUP(G:G,Planilha1!A:A,Planilha1!D:D,"Não encontrado") -> -23.5615395765605
A38: DAC/A.LES.25.01238 | B38: Ligação Nova | C38: 46169 | D38: Liberado para Execução | E38: FI | F38: 16188499 | G38: 010ET080957 | H38: 46169.417 | I38: 46169.583 | J38: Start Engenharia (Área 8B, 9 e 11) NEC | K38: =_xlfn.XLOOKUP(G:G,Planilha1!A:A,Planilha1!C:C,"NÃO ENCONTRADO") -> -46.5213543581439 | L38: =_xlfn.XLOOKUP(G:G,Planilha1!A:A,Planilha1!D:D,"Não encontrado") -> -23.6423791058206
A39: DAC/A.LES.26.00622 | B39: Alteração de Carga | C39: 46169 | D39: Liberado para Execução | E39: FI | F39: 16201235 | G39: 356ET161341 | H39: 46169.583 | I39: 46169.708 | J39: Start Engenharia (Área 8B, 9 e 11) NEC | K39: =_xlfn.XLOOKUP(G:G,Planilha1!A:A,Planilha1!C:C,"NÃO ENCONTRADO") -> -46.4712207533643 | L39: =_xlfn.XLOOKUP(G:G,Planilha1!A:A,Planilha1!D:D,"Não encontrado") -> -23.5930672760876
A40: DAC/A.LES.26.00082 | B40: Ligação Nova | C40: 46169 | D40: Liberado para Execução | E40: FI | F40: 16205972 | G40: 353ET006176 | H40: 46169.417 | I40: 46169.583 | J40: Start Engenharia (Área 8B, 9 e 11) NEC | K40: =_xlfn.XLOOKUP(G:G,Planilha1!A:A,Planilha1!C:C,"NÃO ENCONTRADO") -> -46.5063096920106 | L40: =_xlfn.XLOOKUP(G:G,Planilha1!A:A,Planilha1!D:D,"Não encontrado") -> -23.5321781431308
...

Sheet Planilha1
A1: Numero de Campo | B1: Identificador do Circuito | C1: Localização X (Longitude) | D1: Localização Y (Latitude)
A2: 010BF000180 | B2: UTI 0103 | C2: -46.5323341628012 | D2: -23.6349734314998
A3: 010BF000304 | B3: SND 0102 | C3: -46.5227286861687 | D3: -23.6502573896589
A4: 010BF000347 | B4: CAP 0105 | C4: -46.5094462448598 | D4: -23.679703688558
A5: 010BF000440 | B5: RPI 0102 | C5: -46.3453730456144 | D5: -23.7540352045616
A6: 010BF000441 | B6: RPI 0102 | C6: -46.3481815913462 | D6: -23.7440347597098
A7: 010BF000550 | B7: RGR 0105 | C7: -46.482861514251 | D7: -23.7300736120424
A8: 010BF000637 | B8: SIL 0105 | C8: -46.5469526176571 | D8: -23.6632411737624
A9: 010BF000644 | B9: SIL 0105 | C9: -46.5517714525228 | D9: -23.6667196377997
A10: 010BF000803 | B10: VIT 0108 | C10: -46.5103391396577 | D10: -23.7148838772204
A11: 010BF000822 | B11: VIT 0112 | C11: -46.5166852260199 | D11: -23.6846039823967
A12: 010BF000888 | B12: SND 0103 | C12: -46.517535252496 | D12: -23.6738224441463
... A44222: 356ET166800 | B44222: GNA 0111 | C44222: -46.4394788158636 | D44222: -23.6102363598073
A44223: 356ET166801 | C44223: -46.4366049026648 | D44223: -23.6106089564448
A44224: 356ET166802 | B44224: GNA 0111 | C44224: -46.4383142545894 | D44224: -23.6114231462435
A44225: 356ET166803 | B44225: GNA 0111 | C44225: -46.4377489424643 | D44225: -23.6117894352906
A44226: 356ET166804 | B44226: GNA 0111 | C44226: -46.4358799731482 | D44226: -23.61123915124
A44227: 356ET166805 | B44227: GNA 0111 | C44227: -46.4368016022182 | D44227: -23.6119758439277
A44228: 356ET166806 | B44228: ITR 0106 | C44228: -46.4487821936926 | D44228: -23.5522741035001
A44229: 356ET166808 | B44229: ITR 0115 | C44229: -46.4313158314552 | D44229: -23.5242179158237
A44230: 356ET166810 | B44230: GNA 0107 | C44230: -46.4226047503026 | D44230: -23.6146068084475
A44231: 356ET166812 | B44231: ITN 0111 | C44231: -46.4178850105285 | D44231: -23.5271161455846
A44232: 356ET166813 | B44232: ITN 0103 | C44232: -46.4182496078661 | D44232: -23.5261344111044
A44233: 356ET166814 | B44233: ITN 0103 | C44233: -46.4184106615994 | D44233: -23.5241550762775
A44234: 356ET166820 | B44234: GNA 0103 | C44234: -46.4531484059656 | D44234: -23.5735515821959
A44235: 356ET166821 | B44235: TIR 0109 | C44235: -46.4229220418284 | D44235: -23.5577129668694
... A44254: 356ET166876 | B44254: GNA 0111 | C44254: -46.4320840886886 | D44254: -23.6134240065915
A44255: 356ET166877 | C44255: -46.4321524700777 | D44255: -23.6149184262674
A44256: 356ET166878 | B44256: GNA 0111 | C44256: -46.4313712898767 | D44256: -23.6152826212901
A44257: 356ET166879 | B44257: GNA 0111 | C44257: -46.4308154322592 | D44257: -23.6144199763508
A44258: 356ET166880 | B44258: GNA 0111 | C44258: -46.4346410891568 | D44258: -23.6148301477518
A44259: 356ET166881 | B44259: GNA 0111 | C44259: -46.4334525272303 | D44259: -23.6147103646305
A44260: 356ET166882 | B44260: GNA 0111 | C44260: -46.4357967303602 | D44260: -23.6149686490886
A44261: 356ET166883 | B44261: GNA 0111 | C44261: -46.4319087706515 | D44261: -23.616221201915
A44262: 356ET166884 | B44262: GNA 0111 | C44262: -46.4328817914851 | D44262: -23.6165361556525
A44263: 356ET166885 | B44263: GNA 0111 | C44263: -46.4324021799135 | D44263: -23.6155844014959
A44264: 356ET166886 | B44264: GNA 0111 | C44264: -46.4337050460296 | D44264: -23.6141296991727
A44265: 356ET166887 | B44265: GNA 0111 | C44265: -46.4343453729941 | D44265: -23.6142512973903
A44266: 356ET166888 | B44266: GNA 0111 | C44266: -46.4349317760301 | D44266: -23.6142629447924
A44267: 356ET166889 | B44267: GNA 0111 | C44267: -46.4355223472483 | D44267: -23.6140724420821
...
